<?xml version='1.0' encoding='ASCII'?>
<robot name="niu_s">
  <link name="world"/>
  <link name="base_link">
    <visual>
      <geometry>
        <mesh filename="/home/y/Documents/WYY_META/Planning-on-VKC/src/robot_description/husky_description/meshes/base_link.dae"/>
      </geometry>
      <origin xyz="0.0 0.0 0.0" rpy="0.0 -0.0 0.0"/>
    </visual>
    <collision>
      <geometry>
        <cylinder radius="0.47" length="0.4"/>
      </geometry>
      <origin xyz="0.0 0.0 0.061875" rpy="0.0 -0.0 0.0"/>
    </collision>
  </link>
  <link name="base_footprint"/>
  <link name="inertial_link">
    <inertial>
      <origin xyz="-0.00065 -0.085 0.062" rpy="0.0 -0.0 0.0"/>
      <mass value="46.034"/>
      <inertia ixx="0.6022" ixy="-0.02364" ixz="-0.1197" iyy="1.7386" iyz="-0.001544" izz="2.0296"/>
    </inertial>
  </link>
  <link name="imu_link"/>
  <link name="front_left_wheel_link">
    <inertial>
      <origin xyz="0.0 0.0 0.0" rpy="0.0 -0.0 0.0"/>
      <mass value="2.637"/>
      <inertia ixx="0.02467" ixy="0.0" ixz="0.0" iyy="0.04411" iyz="0.0" izz="0.02467"/>
    </inertial>
    <visual>
      <geometry>
        <mesh filename="/home/y/Documents/WYY_META/Planning-on-VKC/src/robot_description/husky_description/meshes/wheel.dae"/>
      </geometry>
      <origin xyz="0.0 0.0 0.0" rpy="0.0 -0.0 0.0"/>
    </visual>
  </link>
  <link name="front_right_wheel_link">
    <inertial>
      <origin xyz="0.0 0.0 0.0" rpy="0.0 -0.0 0.0"/>
      <mass value="2.637"/>
      <inertia ixx="0.02467" ixy="0.0" ixz="0.0" iyy="0.04411" iyz="0.0" izz="0.02467"/>
    </inertial>
    <visual>
      <geometry>
        <mesh filename="/home/y/Documents/WYY_META/Planning-on-VKC/src/robot_description/husky_description/meshes/wheel.dae"/>
      </geometry>
      <origin xyz="0.0 0.0 0.0" rpy="0.0 -0.0 0.0"/>
    </visual>
  </link>
  <link name="rear_left_wheel_link">
    <inertial>
      <origin xyz="0.0 0.0 0.0" rpy="0.0 -0.0 0.0"/>
      <mass value="2.637"/>
      <inertia ixx="0.02467" ixy="0.0" ixz="0.0" iyy="0.04411" iyz="0.0" izz="0.02467"/>
    </inertial>
    <visual>
      <geometry>
        <mesh filename="/home/y/Documents/WYY_META/Planning-on-VKC/src/robot_description/husky_description/meshes/wheel.dae"/>
      </geometry>
      <origin xyz="0.0 0.0 0.0" rpy="0.0 -0.0 0.0"/>
    </visual>
  </link>
  <link name="rear_right_wheel_link">
    <inertial>
      <origin xyz="0.0 0.0 0.0" rpy="0.0 -0.0 0.0"/>
      <mass value="2.637"/>
      <inertia ixx="0.02467" ixy="0.0" ixz="0.0" iyy="0.04411" iyz="0.0" izz="0.02467"/>
    </inertial>
    <visual>
      <geometry>
        <mesh filename="/home/y/Documents/WYY_META/Planning-on-VKC/src/robot_description/husky_description/meshes/wheel.dae"/>
      </geometry>
      <origin xyz="0.0 0.0 0.0" rpy="0.0 -0.0 0.0"/>
    </visual>
  </link>
  <link name="top_chassis_link">
    <visual>
      <geometry>
        <mesh filename="/home/y/Documents/WYY_META/Planning-on-VKC/src/robot_description/husky_description/meshes/top_chassis.dae"/>
      </geometry>
      <origin xyz="0.0 0.0 0.0" rpy="0.0 -0.0 0.0"/>
    </visual>
  </link>
  <link name="user_rail_link">
    <visual>
      <geometry>
        <mesh filename="/home/y/Documents/WYY_META/Planning-on-VKC/src/robot_description/husky_description/meshes/user_rail.dae"/>
      </geometry>
    </visual>
  </link>
  <link name="front_bumper_link">
    <visual>
      <geometry>
        <mesh filename="/home/y/Documents/WYY_META/Planning-on-VKC/src/robot_description/husky_description/meshes/bumper.dae"/>
      </geometry>
    </visual>
  </link>
  <link name="rear_bumper_link">
    <visual>
      <geometry>
        <mesh filename="/home/y/Documents/WYY_META/Planning-on-VKC/src/robot_description/husky_description/meshes/bumper.dae"/>
      </geometry>
    </visual>
  </link>
  <link name="top_plate_link">
    <visual>
      <geometry>
        <mesh filename="/home/y/Documents/WYY_META/Planning-on-VKC/src/robot_description/husky_description/meshes/top_plate.dae"/>
      </geometry>
      <origin xyz="0.0 0.0 0.0" rpy="0.0 -0.0 0.0"/>
    </visual>
  </link>
  <link name="top_plate_front_link"/>
  <link name="top_plate_rear_link"/>
  <link name="ur_arm_base_link">
    <inertial>
      <origin xyz="0.0 0.0 0.0" rpy="0.0 -0.0 0.0"/>
      <mass value="4.0"/>
      <inertia ixx="0.00443333156" ixy="0.0" ixz="0.0" iyy="0.00443333156" iyz="0.0" izz="0.0072"/>
    </inertial>
    <visual>
      <geometry>
        <mesh filename="/home/y/Documents/WYY_META/Planning-on-VKC/src/robot_description/ur_e_description/meshes/ur5e/visual/base.dae"/>
      </geometry>
      <material name="LightGrey">
        <color rgba="0.7 0.7 0.7 1.0"/>
      </material>
    </visual>
    <collision>
      <geometry>
        <mesh filename="/home/y/Documents/WYY_META/Planning-on-VKC/src/robot_description/ur_e_description/meshes/ur5e/collision/base.stl"/>
      </geometry>
    </collision>
  </link>
  <link name="ur_arm_shoulder_link">
    <inertial>
      <origin xyz="0.0 0.0 0.0" rpy="0.0 -0.0 0.0"/>
      <mass value="3.7"/>
      <inertia ixx="0.010267495893" ixy="0.0" ixz="0.0" iyy="0.010267495893" iyz="0.0" izz="0.00666"/>
    </inertial>
    <visual>
      <geometry>
        <mesh filename="/home/y/Documents/WYY_META/Planning-on-VKC/src/robot_description/ur_e_description/meshes/ur5e/visual/shoulder.dae"/>
      </geometry>
      <material name="LightGrey">
        <color rgba="0.7 0.7 0.7 1.0"/>
      </material>
    </visual>
    <collision>
      <geometry>
        <mesh filename="/home/y/Documents/WYY_META/Planning-on-VKC/src/robot_description/ur_e_description/meshes/ur5e/collision/shoulder.stl"/>
      </geometry>
    </collision>
  </link>
  <link name="ur_arm_upper_arm_link">
    <inertial>
      <origin xyz="0.0 0.0 0.2125" rpy="0.0 -0.0 0.0"/>
      <mass value="8.393"/>
      <inertia ixx="0.1338857818623325" ixy="0.0" ixz="0.0" iyy="0.1338857818623325" iyz="0.0" izz="0.0151074"/>
    </inertial>
    <visual>
      <geometry>
        <mesh filename="/home/y/Documents/WYY_META/Planning-on-VKC/src/robot_description/ur_e_description/meshes/ur5e/visual/upperarm.dae"/>
      </geometry>
      <material name="LightGrey">
        <color rgba="0.7 0.7 0.7 1.0"/>
      </material>
    </visual>
    <collision>
      <geometry>
        <mesh filename="/home/y/Documents/WYY_META/Planning-on-VKC/src/robot_description/ur_e_description/meshes/ur5e/collision/upperarm.stl"/>
      </geometry>
    </collision>
  </link>
  <link name="ur_arm_forearm_link">
    <inertial>
      <origin xyz="0.0 0.0 0.196" rpy="0.0 -0.0 0.0"/>
      <mass value="2.275"/>
      <inertia ixx="0.031179620861480004" ixy="0.0" ixz="0.0" iyy="0.031179620861480004" iyz="0.0" izz="0.004095"/>
    </inertial>
    <visual>
      <geometry>
        <mesh filename="/home/y/Documents/WYY_META/Planning-on-VKC/src/robot_description/ur_e_description/meshes/ur5e/visual/forearm.dae"/>
      </geometry>
      <material name="LightGrey">
        <color rgba="0.7 0.7 0.7 1.0"/>
      </material>
    </visual>
    <collision>
      <geometry>
        <mesh filename="/home/y/Documents/WYY_META/Planning-on-VKC/src/robot_description/ur_e_description/meshes/ur5e/collision/forearm.stl"/>
      </geometry>
    </collision>
  </link>
  <link name="ur_arm_wrist_1_link">
    <inertial>
      <origin xyz="0.0 0.127 0.0" rpy="0.0 -0.0 0.0"/>
      <mass value="1.219"/>
      <inertia ixx="0.0025598989760400002" ixy="0.0" ixz="0.0" iyy="0.0025598989760400002" iyz="0.0" izz="0.0021942"/>
    </inertial>
    <visual>
      <geometry>
        <mesh filename="/home/y/Documents/WYY_META/Planning-on-VKC/src/robot_description/ur_e_description/meshes/ur5e/visual/wrist1.dae"/>
      </geometry>
      <material name="LightGrey">
        <color rgba="0.7 0.7 0.7 1.0"/>
      </material>
    </visual>
    <collision>
      <geometry>
        <mesh filename="/home/y/Documents/WYY_META/Planning-on-VKC/src/robot_description/ur_e_description/meshes/ur5e/collision/wrist1.stl"/>
      </geometry>
    </collision>
  </link>
  <link name="ur_arm_wrist_2_link">
    <inertial>
      <origin xyz="0.0 0.0 0.1" rpy="0.0 -0.0 0.0"/>
      <mass value="1.219"/>
      <inertia ixx="0.0025598989760400002" ixy="0.0" ixz="0.0" iyy="0.0025598989760400002" iyz="0.0" izz="0.0021942"/>
    </inertial>
    <visual>
      <geometry>
        <mesh filename="/home/y/Documents/WYY_META/Planning-on-VKC/src/robot_description/ur_e_description/meshes/ur5e/visual/wrist2.dae"/>
      </geometry>
      <material name="LightGrey">
        <color rgba="0.7 0.7 0.7 1.0"/>
      </material>
    </visual>
    <collision>
      <geometry>
        <mesh filename="/home/y/Documents/WYY_META/Planning-on-VKC/src/robot_description/ur_e_description/meshes/ur5e/collision/wrist2.stl"/>
      </geometry>
    </collision>
  </link>
  <link name="ur_arm_wrist_3_link">
    <inertial>
      <origin xyz="0.0 0.0771 0.0" rpy="1.5707963267948966 -0.0 0.0"/>
      <mass value="0.1879"/>
      <inertia ixx="9.890410052167731e-05" ixy="0.0" ixz="0.0" iyy="9.890410052167731e-05" iyz="0.0" izz="0.0001321171875"/>
    </inertial>
    <visual>
      <geometry>
        <mesh filename="/home/y/Documents/WYY_META/Planning-on-VKC/src/robot_description/ur_e_description/meshes/ur5e/visual/wrist3.dae"/>
      </geometry>
      <material name="LightGrey">
        <color rgba="0.7 0.7 0.7 1.0"/>
      </material>
    </visual>
    <collision>
      <geometry>
        <mesh filename="/home/y/Documents/WYY_META/Planning-on-VKC/src/robot_description/ur_e_description/meshes/ur5e/collision/wrist3.stl"/>
      </geometry>
    </collision>
  </link>
  <link name="ur_arm_ee_link">
    <collision>
      <geometry>
        <box size="0.01 0.01 0.01"/>
      </geometry>
      <origin xyz="-0.01 0.0 0.0" rpy="0.0 -0.0 0.0"/>
    </collision>
  </link>
  <link name="ur_arm_base"/>
  <link name="ur_arm_tool0"/>
  <link name="world"/>
  <link name="virtual_base_x"/>
  <link name="virtual_base_y"/>
  <link name="virtual_base_theta"/>
  <link name="robotiq_arg2f_base_link">
    <inertial>
      <origin xyz="8.625e-08 -4.6583e-06 0.03145" rpy="0.0 -0.0 0.0"/>
      <mass value="0.22652"/>
      <inertia ixx="0.00020005" ixy="-4.2442e-10" ixz="-2.9069e-10" iyy="0.00017832" iyz="-3.4402e-08" izz="0.00013478"/>
    </inertial>
    <visual>
      <geometry>
        <mesh filename="/home/y/Documents/WYY_META/Planning-on-VKC/src/robot_description/robotiq_2f_85_gripper_visualization/meshes/visual/robotiq_arg2f_85_base_link.dae" scale="0.001 0.001 0.001"/>
      </geometry>
      <origin xyz="0.0 0.0 0.0" rpy="0.0 -0.0 0.0"/>
      <material name="">
        <color rgba="0.1 0.1 0.1 1.0"/>
      </material>
    </visual>
    <collision>
      <geometry>
        <mesh filename="/home/y/Documents/WYY_META/Planning-on-VKC/src/robot_description/robotiq_2f_85_gripper_visualization/meshes/collision/robotiq_arg2f_base_link.stl"/>
      </geometry>
      <origin xyz="0.0 0.0 0.0" rpy="0.0 -0.0 0.0"/>
    </collision>
  </link>
  <link name="left_outer_knuckle">
    <visual>
      <geometry>
        <mesh filename="/home/y/Documents/WYY_META/Planning-on-VKC/src/robot_description/robotiq_2f_85_gripper_visualization/meshes/visual/robotiq_arg2f_85_outer_knuckle.dae" scale="0.001 0.001 0.001"/>
      </geometry>
      <origin xyz="0.0 0.0 0.0" rpy="0.0 -0.0 0.0"/>
      <material name="">
        <color rgba="0.792156862745098 0.819607843137255 0.933333333333333 1.0"/>
      </material>
    </visual>
  </link>
  <link name="left_outer_finger">
    <visual>
      <geometry>
        <mesh filename="/home/y/Documents/WYY_META/Planning-on-VKC/src/robot_description/robotiq_2f_85_gripper_visualization/meshes/visual/robotiq_arg2f_85_outer_finger.dae" scale="0.001 0.001 0.001"/>
      </geometry>
      <origin xyz="0.0 0.0 0.0" rpy="0.0 -0.0 0.0"/>
      <material name="">
        <color rgba="0.1 0.1 0.1 1.0"/>
      </material>
    </visual>
  </link>
  <link name="left_inner_finger">
    <visual>
      <geometry>
        <mesh filename="/home/y/Documents/WYY_META/Planning-on-VKC/src/robot_description/robotiq_2f_85_gripper_visualization/meshes/visual/robotiq_arg2f_85_inner_finger.dae" scale="0.001 0.001 0.001"/>
      </geometry>
      <origin xyz="0.0 0.0 0.0" rpy="0.0 -0.0 0.0"/>
      <material name="">
        <color rgba="0.1 0.1 0.1 1.0"/>
      </material>
    </visual>
  </link>
  <link name="left_inner_finger_pad">
    <visual>
      <geometry>
        <box size="0.022 0.00635 0.0375"/>
      </geometry>
      <origin xyz="0.0 0.0 0.0" rpy="0.0 -0.0 0.0"/>
      <material name="">
        <color rgba="0.9 0.9 0.9 1.0"/>
      </material>
    </visual>
  </link>
  <link name="left_inner_knuckle">
    <visual>
      <geometry>
        <mesh filename="/home/y/Documents/WYY_META/Planning-on-VKC/src/robot_description/robotiq_2f_85_gripper_visualization/meshes/visual/robotiq_arg2f_85_inner_knuckle.dae" scale="0.001 0.001 0.001"/>
      </geometry>
      <origin xyz="0.0 0.0 0.0" rpy="0.0 -0.0 0.0"/>
      <material name="">
        <color rgba="0.1 0.1 0.1 1.0"/>
      </material>
    </visual>
  </link>
  <link name="right_outer_knuckle">
    <visual>
      <geometry>
        <mesh filename="/home/y/Documents/WYY_META/Planning-on-VKC/src/robot_description/robotiq_2f_85_gripper_visualization/meshes/visual/robotiq_arg2f_85_outer_knuckle.dae" scale="0.001 0.001 0.001"/>
      </geometry>
      <origin xyz="0.0 0.0 0.0" rpy="0.0 -0.0 0.0"/>
      <material name="">
        <color rgba="0.792156862745098 0.819607843137255 0.933333333333333 1.0"/>
      </material>
    </visual>
  </link>
  <link name="right_outer_finger">
    <visual>
      <geometry>
        <mesh filename="/home/y/Documents/WYY_META/Planning-on-VKC/src/robot_description/robotiq_2f_85_gripper_visualization/meshes/visual/robotiq_arg2f_85_outer_finger.dae" scale="0.001 0.001 0.001"/>
      </geometry>
      <origin xyz="0.0 0.0 0.0" rpy="0.0 -0.0 0.0"/>
      <material name="">
        <color rgba="0.1 0.1 0.1 1.0"/>
      </material>
    </visual>
  </link>
  <link name="right_inner_finger">
    <visual>
      <geometry>
        <mesh filename="/home/y/Documents/WYY_META/Planning-on-VKC/src/robot_description/robotiq_2f_85_gripper_visualization/meshes/visual/robotiq_arg2f_85_inner_finger.dae" scale="0.001 0.001 0.001"/>
      </geometry>
      <origin xyz="0.0 0.0 0.0" rpy="0.0 -0.0 0.0"/>
      <material name="">
        <color rgba="0.1 0.1 0.1 1.0"/>
      </material>
    </visual>
  </link>
  <link name="right_inner_finger_pad">
    <visual>
      <geometry>
        <box size="0.022 0.00635 0.0375"/>
      </geometry>
      <origin xyz="0.0 0.0 0.0" rpy="0.0 -0.0 0.0"/>
      <material name="">
        <color rgba="0.9 0.9 0.9 1.0"/>
      </material>
    </visual>
  </link>
  <link name="right_inner_knuckle">
    <visual>
      <geometry>
        <mesh filename="/home/y/Documents/WYY_META/Planning-on-VKC/src/robot_description/robotiq_2f_85_gripper_visualization/meshes/visual/robotiq_arg2f_85_inner_knuckle.dae" scale="0.001 0.001 0.001"/>
      </geometry>
      <origin xyz="0.0 0.0 0.0" rpy="0.0 -0.0 0.0"/>
      <material name="">
        <color rgba="0.1 0.1 0.1 1.0"/>
      </material>
    </visual>
  </link>
  <link name="swivel_chair_base">
    <visual>
      <geometry>
        <mesh filename="/home/y/Documents/WYY_META/SR_exp/effectit/VKC/src/env_description/household_env/assets/rigid/meshes/94e289c89059106bd8f74b0004a598cd/model_normalized.obj" scale="1.2 1.2 1.2"/>
      </geometry>
      <origin xyz="0.0 0.0 0.0" rpy="0.0 -0.0 0.0"/>
    </visual>
    <collision>
      <geometry>
        <mesh filename="/home/y/Documents/WYY_META/SR_exp/effectit/VKC/src/env_description/household_env/assets/rigid/meshes/94e289c89059106bd8f74b0004a598cd/model_normalized.obj" scale="1.2 1.2 1.2"/>
      </geometry>
      <origin xyz="0.0 0.0 0.0" rpy="0.0 -0.0 0.0"/>
    </collision>
  </link>
  <link name="swivel_chair_virtual_theta_link"/>
  <link name="swivel_chair_virtual_y_link"/>
  <link name="swivel_chair_virtual_x_link"/>
  <link name="swivel_chair_base_link"/>
  <joint name="hur5e_world2base_joint" type="fixed">
    <parent link="world"/>
    <child link="base_link"/>
    <origin xyz="0.0 0.0 0.0" rpy="0.0 -0.0 0.0"/>
  </joint>
  <joint name="base_footprint_joint" type="fixed">
    <parent link="base_link"/>
    <child link="base_footprint"/>
    <origin xyz="0.0 0.0 -0.13228" rpy="0.0 -0.0 0.0"/>
    <axis xyz="1.0 0.0 0.0"/>
  </joint>
  <joint name="inertial_joint" type="fixed">
    <parent link="base_link"/>
    <child link="inertial_link"/>
    <origin xyz="0.0 0.0 0.0" rpy="0.0 -0.0 0.0"/>
    <axis xyz="1.0 0.0 0.0"/>
  </joint>
  <joint name="imu_joint" type="fixed">
    <parent link="base_link"/>
    <child link="imu_link"/>
    <origin xyz="0.19 0.0 0.149" rpy="3.141592653589793 -1.5707926535897934 7.346410206709668e-06"/>
    <axis xyz="1.0 0.0 0.0"/>
  </joint>
  <joint name="front_left_wheel" type="fixed">
    <parent link="base_link"/>
    <child link="front_left_wheel_link"/>
    <origin xyz="0.256 0.2854 0.03282" rpy="0.0 -0.0 0.0"/>
    <axis xyz="0.0 1.0 0.0"/>
  </joint>
  <joint name="front_right_wheel" type="fixed">
    <parent link="base_link"/>
    <child link="front_right_wheel_link"/>
    <origin xyz="0.256 -0.2854 0.03282" rpy="0.0 -0.0 0.0"/>
    <axis xyz="0.0 1.0 0.0"/>
  </joint>
  <joint name="rear_left_wheel" type="fixed">
    <parent link="base_link"/>
    <child link="rear_left_wheel_link"/>
    <origin xyz="-0.256 0.2854 0.03282" rpy="0.0 -0.0 0.0"/>
    <axis xyz="0.0 1.0 0.0"/>
  </joint>
  <joint name="rear_right_wheel" type="fixed">
    <parent link="base_link"/>
    <child link="rear_right_wheel_link"/>
    <origin xyz="-0.256 -0.2854 0.03282" rpy="0.0 -0.0 0.0"/>
    <axis xyz="0.0 1.0 0.0"/>
  </joint>
  <joint name="top_chassis_joint" type="fixed">
    <parent link="base_link"/>
    <child link="top_chassis_link"/>
    <axis xyz="1.0 0.0 0.0"/>
  </joint>
  <joint name="user_rail" type="fixed">
    <parent link="base_link"/>
    <child link="user_rail_link"/>
    <origin xyz="0.272 0.0 0.245" rpy="0.0 -0.0 0.0"/>
    <axis xyz="1.0 0.0 0.0"/>
  </joint>
  <joint name="front_bumper" type="fixed">
    <parent link="base_link"/>
    <child link="front_bumper_link"/>
    <origin xyz="0.48 0.0 0.091" rpy="0.0 -0.0 0.0"/>
    <axis xyz="1.0 0.0 0.0"/>
  </joint>
  <joint name="rear_bumper" type="fixed">
    <parent link="base_link"/>
    <child link="rear_bumper_link"/>
    <origin xyz="-0.48 0.0 0.091" rpy="0.0 -0.0 3.14159"/>
    <axis xyz="1.0 0.0 0.0"/>
  </joint>
  <joint name="top_plate_joint" type="fixed">
    <parent link="base_link"/>
    <child link="top_plate_link"/>
    <origin xyz="0.0812 0.0 0.245" rpy="0.0 -0.0 0.0"/>
    <axis xyz="1.0 0.0 0.0"/>
  </joint>
  <joint name="top_plate_front_joint" type="fixed">
    <parent link="top_plate_link"/>
    <child link="top_plate_front_link"/>
    <origin xyz="0.36367 0.0 0.00639" rpy="0.0 -0.0 0.0"/>
    <axis xyz="1.0 0.0 0.0"/>
  </joint>
  <joint name="top_plate_rear_joint" type="fixed">
    <parent link="top_plate_link"/>
    <child link="top_plate_rear_link"/>
    <origin xyz="-0.36633 0.0 0.00639" rpy="0.0 -0.0 0.0"/>
    <axis xyz="1.0 0.0 0.0"/>
  </joint>
  <joint name="arm_mount_joint" type="fixed">
    <parent link="top_plate_link"/>
    <child link="ur_arm_base_link"/>
    <origin xyz="-0.08122 0.0 0.0" rpy="0.0 -0.0 -3.1415926071795868"/>
    <axis xyz="1.0 0.0 0.0"/>
  </joint>
  <joint name="ur_arm_shoulder_pan_joint" type="revolute">
    <parent link="ur_arm_base_link"/>
    <child link="ur_arm_shoulder_link"/>
    <origin xyz="0.0 0.0 0.163" rpy="0.0 -0.0 0.0"/>
    <axis xyz="0.0 0.0 1.0"/>
    <limit effort="150.0" velocity="3.14" lower="-3.141592653589793" upper="3.141592653589793"/>
    <dynamics damping="0.0" friction="0.0"/>
  </joint>
  <joint name="ur_arm_shoulder_lift_joint" type="revolute">
    <parent link="ur_arm_shoulder_link"/>
    <child link="ur_arm_upper_arm_link"/>
    <origin xyz="0.0 0.138 0.0" rpy="-0.0 1.5707963267948966 0.0"/>
    <axis xyz="0.0 1.0 0.0"/>
    <limit effort="150.0" velocity="3.14" lower="-3.141592653589793" upper="3.141592653589793"/>
    <dynamics damping="0.0" friction="0.0"/>
  </joint>
  <joint name="ur_arm_elbow_joint" type="revolute">
    <parent link="ur_arm_upper_arm_link"/>
    <child link="ur_arm_forearm_link"/>
    <origin xyz="0.0 -0.131 0.425" rpy="0.0 -0.0 0.0"/>
    <axis xyz="0.0 1.0 0.0"/>
    <limit effort="150.0" velocity="3.14" lower="-3.141592653589793" upper="3.141592653589793"/>
    <dynamics damping="0.0" friction="0.0"/>
  </joint>
  <joint name="ur_arm_wrist_1_joint" type="revolute">
    <parent link="ur_arm_forearm_link"/>
    <child link="ur_arm_wrist_1_link"/>
    <origin xyz="0.0 0.0 0.392" rpy="-0.0 1.5707963267948966 0.0"/>
    <axis xyz="0.0 1.0 0.0"/>
    <limit effort="28.0" velocity="6.28" lower="-3.141592653589793" upper="3.141592653589793"/>
    <dynamics damping="0.0" friction="0.0"/>
  </joint>
  <joint name="ur_arm_wrist_2_joint" type="revolute">
    <parent link="ur_arm_wrist_1_link"/>
    <child link="ur_arm_wrist_2_link"/>
    <origin xyz="0.0 0.127 0.0" rpy="0.0 -0.0 0.0"/>
    <axis xyz="0.0 0.0 1.0"/>
    <limit effort="28.0" velocity="6.28" lower="-3.141592653589793" upper="3.141592653589793"/>
    <dynamics damping="0.0" friction="0.0"/>
  </joint>
  <joint name="ur_arm_wrist_3_joint" type="revolute">
    <parent link="ur_arm_wrist_2_link"/>
    <child link="ur_arm_wrist_3_link"/>
    <origin xyz="0.0 0.0 0.1" rpy="0.0 -0.0 0.0"/>
    <axis xyz="0.0 1.0 0.0"/>
    <limit effort="28.0" velocity="6.28" lower="-3.141592653589793" upper="3.141592653589793"/>
    <dynamics damping="0.0" friction="0.0"/>
  </joint>
  <joint name="ur_arm_ee_fixed_joint" type="fixed">
    <parent link="ur_arm_wrist_3_link"/>
    <child link="ur_arm_ee_link"/>
    <origin xyz="0.0 0.1 0.0" rpy="0.0 -0.0 1.5707963267948966"/>
    <axis xyz="1.0 0.0 0.0"/>
  </joint>
  <joint name="ur_arm_base_link-base_fixed_joint" type="fixed">
    <parent link="ur_arm_base_link"/>
    <child link="ur_arm_base"/>
    <origin xyz="0.0 0.0 0.0" rpy="0.0 -0.0 -3.141592653589793"/>
    <axis xyz="1.0 0.0 0.0"/>
  </joint>
  <joint name="ur_arm_ee_link-tool0_fixed_joint" type="fixed">
    <parent link="ur_arm_ee_link"/>
    <child link="ur_arm_tool0"/>
    <origin xyz="0.2 0.0 0.0" rpy="0.0 1.57 1.57"/>
    <axis xyz="1.0 0.0 0.0"/>
  </joint>
  <joint name="2f_85_joint" type="fixed">
    <parent link="ur_arm_ee_link"/>
    <child link="robotiq_arg2f_base_link"/>
    <origin xyz="0.0 0.0 0.0" rpy="0.0 1.570795 0.0"/>
    <axis xyz="1.0 0.0 0.0"/>
  </joint>
  <joint name="base_link_base_theta" type="revolute">
    <parent link="virtual_base_theta"/>
    <child link="base_link"/>
    <origin xyz="0.0 0.0 0.0" rpy="0.0 -0.0 0.0"/>
    <axis xyz="0.0 0.0 1.0"/>
    <limit effort="20.0" velocity="5.0" lower="-3.14" upper="3.14"/>
  </joint>
  <joint name="base_theta_base_y" type="prismatic">
    <parent link="virtual_base_y"/>
    <child link="virtual_base_theta"/>
    <origin xyz="0.0 0.0 0.0" rpy="0.0 -0.0 0.0"/>
    <axis xyz="0.0 1.0 0.0"/>
    <limit effort="20.0" velocity="5.0" lower="-10.0" upper="10.0"/>
  </joint>
  <joint name="base_y_base_x" type="prismatic">
    <parent link="virtual_base_x"/>
    <child link="virtual_base_y"/>
    <origin xyz="0.0 0.0 0.0" rpy="0.0 -0.0 0.0"/>
    <axis xyz="1.0 0.0 0.0"/>
    <limit effort="20.0" velocity="5.0" lower="-10.0" upper="10.0"/>
  </joint>
  <joint name="world" type="fixed">
    <parent link="world"/>
    <child link="virtual_base_x"/>
    <origin xyz="0.0 0.0 0.145" rpy="0.0 -0.0 0.0"/>
    <axis xyz="1.0 0.0 0.0"/>
  </joint>
  <joint name="finger_joint" type="fixed">
    <parent link="robotiq_arg2f_base_link"/>
    <child link="left_outer_knuckle"/>
    <origin xyz="0.0 -0.0306011 0.054904" rpy="0.0 -0.0 3.141592653589793"/>
    <axis xyz="1.0 0.0 0.0"/>
    <limit effort="1000.0" velocity="2.0" lower="0.0" upper="0.8"/>
  </joint>
  <joint name="left_outer_finger_joint" type="fixed">
    <parent link="left_outer_knuckle"/>
    <child link="left_outer_finger"/>
    <origin xyz="0.0 0.0315 -0.0041" rpy="0.0 -0.0 0.0"/>
    <axis xyz="1.0 0.0 0.0"/>
  </joint>
  <joint name="left_inner_knuckle_joint" type="fixed">
    <parent link="robotiq_arg2f_base_link"/>
    <child link="left_inner_knuckle"/>
    <origin xyz="0.0 -0.0127 0.06142" rpy="0.0 -0.0 3.141592653589793"/>
    <axis xyz="1.0 0.0 0.0"/>
    <limit effort="1000.0" velocity="2.0" lower="0.0" upper="0.8757"/>
  </joint>
  <joint name="left_inner_finger_joint" type="fixed">
    <parent link="left_outer_finger"/>
    <child link="left_inner_finger"/>
    <origin xyz="0.0 0.0061 0.0471" rpy="0.0 -0.0 0.0"/>
    <axis xyz="1.0 0.0 0.0"/>
    <limit effort="1000.0" velocity="2.0" lower="0.0" upper="0.8757"/>
  </joint>
  <joint name="left_inner_finger_pad_joint" type="fixed">
    <parent link="left_inner_finger"/>
    <child link="left_inner_finger_pad"/>
    <origin xyz="0.0 -0.0220203446692936 0.03242" rpy="0.0 -0.0 0.0"/>
    <axis xyz="0.0 0.0 1.0"/>
  </joint>
  <joint name="right_outer_knuckle_joint" type="fixed">
    <parent link="robotiq_arg2f_base_link"/>
    <child link="right_outer_knuckle"/>
    <origin xyz="0.0 0.0306011 0.054904" rpy="0.0 -0.0 0.0"/>
    <axis xyz="1.0 0.0 0.0"/>
    <limit effort="1000.0" velocity="2.0" lower="0.0" upper="0.81"/>
  </joint>
  <joint name="right_outer_finger_joint" type="fixed">
    <parent link="right_outer_knuckle"/>
    <child link="right_outer_finger"/>
    <origin xyz="0.0 0.0315 -0.0041" rpy="0.0 -0.0 0.0"/>
    <axis xyz="1.0 0.0 0.0"/>
  </joint>
  <joint name="right_inner_knuckle_joint" type="fixed">
    <parent link="robotiq_arg2f_base_link"/>
    <child link="right_inner_knuckle"/>
    <origin xyz="0.0 0.0127 0.06142" rpy="0.0 -0.0 0.0"/>
    <axis xyz="1.0 0.0 0.0"/>
    <limit effort="1000.0" velocity="2.0" lower="0.0" upper="0.8757"/>
  </joint>
  <joint name="right_inner_finger_joint" type="fixed">
    <parent link="right_outer_finger"/>
    <child link="right_inner_finger"/>
    <origin xyz="0.0 0.0061 0.0471" rpy="0.0 -0.0 0.0"/>
    <axis xyz="1.0 0.0 0.0"/>
    <limit effort="1000.0" velocity="2.0" lower="0.0" upper="0.8757"/>
  </joint>
  <joint name="right_inner_finger_pad_joint" type="fixed">
    <parent link="right_inner_finger"/>
    <child link="right_inner_finger_pad"/>
    <origin xyz="0.0 -0.0220203446692936 0.03242" rpy="0.0 -0.0 0.0"/>
    <axis xyz="0.0 0.0 1.0"/>
  </joint>
  <joint name="swivel_chair_base" type="fixed">
    <parent link="robotiq_arg2f_base_link"/>
    <child link="swivel_chair_base"/>
    <origin xyz="0.0 -0.35 0.35" rpy="-3.14 -0.0 -3.14"/>
    <axis xyz="1.0 0.0 0.0"/>
  </joint>
  <joint name="swivel_chair_base" type="fixed">
    <parent link="robotiq_arg2f_base_link"/>
    <child link="swivel_chair_base"/>
    <origin xyz="0.0 -0.35 0.35" rpy="-3.14 -0.0 -3.14"/>
    <axis xyz="1.0 0.0 0.0"/>
  </joint>
  <joint name="swivel_chair_base" type="fixed">
    <parent link="robotiq_arg2f_base_link"/>
    <child link="swivel_chair_base"/>
    <origin xyz="0.0 -0.35 0.35" rpy="-3.14 -0.0 -3.14"/>
    <axis xyz="1.0 0.0 0.0"/>
  </joint>
  <joint name="swivel_chair_base" type="fixed">
    <parent link="robotiq_arg2f_base_link"/>
    <child link="swivel_chair_base"/>
    <origin xyz="0.0 -0.35 0.35" rpy="-3.14 -0.0 -3.14"/>
    <axis xyz="1.0 0.0 0.0"/>
  </joint>
  <joint name="swivel_chair_base" type="fixed">
    <parent link="robotiq_arg2f_base_link"/>
    <child link="swivel_chair_base"/>
    <origin xyz="0.0 -0.35 0.35" rpy="-3.14 -0.0 -3.14"/>
    <axis xyz="1.0 0.0 0.0"/>
  </joint>
  <joint name="swivel_chair_base" type="fixed">
    <parent link="robotiq_arg2f_base_link"/>
    <child link="swivel_chair_base"/>
    <origin xyz="0.0 -0.35 0.35" rpy="-3.14 -0.0 -3.14"/>
    <axis xyz="1.0 0.0 0.0"/>
  </joint>
  <joint name="swivel_chair_base" type="fixed">
    <parent link="robotiq_arg2f_base_link"/>
    <child link="swivel_chair_base"/>
    <origin xyz="0.0 -0.35 0.35" rpy="-3.14 -0.0 -3.14"/>
    <axis xyz="1.0 0.0 0.0"/>
  </joint>
  <joint name="swivel_chair_base" type="fixed">
    <parent link="robotiq_arg2f_base_link"/>
    <child link="swivel_chair_base"/>
    <origin xyz="0.0 -0.35 0.35" rpy="-3.14 -0.0 -3.14"/>
    <axis xyz="1.0 0.0 0.0"/>
  </joint>
  <joint name="swivel_chair_base" type="fixed">
    <parent link="robotiq_arg2f_base_link"/>
    <child link="swivel_chair_base"/>
    <origin xyz="0.0 -0.35 0.35" rpy="-3.14 -0.0 -3.14"/>
    <axis xyz="1.0 0.0 0.0"/>
  </joint>
  <joint name="swivel_chair_base" type="fixed">
    <parent link="robotiq_arg2f_base_link"/>
    <child link="swivel_chair_base"/>
    <origin xyz="0.0 -0.35 0.35" rpy="-3.14 -0.0 -3.14"/>
    <axis xyz="1.0 0.0 0.0"/>
  </joint>
  <joint name="swivel_chair_base" type="fixed">
    <parent link="robotiq_arg2f_base_link"/>
    <child link="swivel_chair_base"/>
    <origin xyz="0.0 -0.35 0.35" rpy="-3.14 -0.0 -3.14"/>
    <axis xyz="1.0 0.0 0.0"/>
  </joint>
  <joint name="swivel_chair_base" type="fixed">
    <parent link="robotiq_arg2f_base_link"/>
    <child link="swivel_chair_base"/>
    <origin xyz="0.0 -0.35 0.35" rpy="-3.14 -0.0 -3.14"/>
    <axis xyz="1.0 0.0 0.0"/>
  </joint>
  <joint name="swivel_chair_base" type="fixed">
    <parent link="robotiq_arg2f_base_link"/>
    <child link="swivel_chair_base"/>
    <origin xyz="0.0 -0.35 0.35" rpy="-3.14 -0.0 -3.14"/>
    <axis xyz="1.0 0.0 0.0"/>
  </joint>
  <joint name="swivel_chair_base" type="fixed">
    <parent link="robotiq_arg2f_base_link"/>
    <child link="swivel_chair_base"/>
    <origin xyz="0.0 -0.35 0.35" rpy="-3.14 -0.0 -3.14"/>
    <axis xyz="1.0 0.0 0.0"/>
  </joint>
  <joint name="swivel_chair_base" type="fixed">
    <parent link="robotiq_arg2f_base_link"/>
    <child link="swivel_chair_base"/>
    <origin xyz="0.0 -0.35 0.35" rpy="-3.14 -0.0 -3.14"/>
    <axis xyz="1.0 0.0 0.0"/>
  </joint>
  <joint name="swivel_chair_base" type="fixed">
    <parent link="robotiq_arg2f_base_link"/>
    <child link="swivel_chair_base"/>
    <origin xyz="0.0 -0.35 0.35" rpy="-3.14 -0.0 -3.14"/>
    <axis xyz="1.0 0.0 0.0"/>
  </joint>
  <joint name="swivel_chair_base" type="fixed">
    <parent link="robotiq_arg2f_base_link"/>
    <child link="swivel_chair_base"/>
    <origin xyz="0.0 -0.35 0.35" rpy="-3.14 -0.0 -3.14"/>
    <axis xyz="1.0 0.0 0.0"/>
  </joint>
  <joint name="swivel_chair_base" type="fixed">
    <parent link="robotiq_arg2f_base_link"/>
    <child link="swivel_chair_base"/>
    <origin xyz="0.0 -0.35 0.35" rpy="-3.14 -0.0 -3.14"/>
    <axis xyz="1.0 0.0 0.0"/>
  </joint>
  <joint name="swivel_chair_base" type="fixed">
    <parent link="robotiq_arg2f_base_link"/>
    <child link="swivel_chair_base"/>
    <origin xyz="0.0 -0.35 0.35" rpy="-3.14 -0.0 -3.14"/>
    <axis xyz="1.0 0.0 0.0"/>
  </joint>
  <joint name="swivel_chair_base" type="fixed">
    <parent link="robotiq_arg2f_base_link"/>
    <child link="swivel_chair_base"/>
    <origin xyz="0.0 -0.35 0.35" rpy="-3.14 -0.0 -3.14"/>
    <axis xyz="1.0 0.0 0.0"/>
  </joint>
  <joint name="swivel_chair_base" type="fixed">
    <parent link="robotiq_arg2f_base_link"/>
    <child link="swivel_chair_base"/>
    <origin xyz="0.0 -0.35 0.35" rpy="-3.14 -0.0 -3.14"/>
    <axis xyz="1.0 0.0 0.0"/>
  </joint>
  <joint name="swivel_chair_base" type="fixed">
    <parent link="robotiq_arg2f_base_link"/>
    <child link="swivel_chair_base"/>
    <origin xyz="0.0 -0.35 0.35" rpy="-3.14 -0.0 -3.14"/>
    <axis xyz="1.0 0.0 0.0"/>
  </joint>
  <joint name="swivel_chair_base" type="fixed">
    <parent link="robotiq_arg2f_base_link"/>
    <child link="swivel_chair_base"/>
    <origin xyz="0.0 -0.35 0.35" rpy="-3.14 -0.0 -3.14"/>
    <axis xyz="1.0 0.0 0.0"/>
  </joint>
  <joint name="swivel_chair_base" type="fixed">
    <parent link="robotiq_arg2f_base_link"/>
    <child link="swivel_chair_base"/>
    <origin xyz="0.0 -0.35 0.35" rpy="-3.14 -0.0 -3.14"/>
    <axis xyz="1.0 0.0 0.0"/>
  </joint>
  <joint name="swivel_chair_base" type="fixed">
    <parent link="robotiq_arg2f_base_link"/>
    <child link="swivel_chair_base"/>
    <origin xyz="0.0 -0.35 0.35" rpy="-3.14 -0.0 -3.14"/>
    <axis xyz="1.0 0.0 0.0"/>
  </joint>
  <joint name="swivel_chair_base" type="fixed">
    <parent link="robotiq_arg2f_base_link"/>
    <child link="swivel_chair_base"/>
    <origin xyz="0.0 -0.35 0.35" rpy="-3.14 -0.0 -3.14"/>
    <axis xyz="1.0 0.0 0.0"/>
  </joint>
  <joint name="swivel_chair_base" type="fixed">
    <parent link="robotiq_arg2f_base_link"/>
    <child link="swivel_chair_base"/>
    <origin xyz="0.0 -0.35 0.35" rpy="-3.14 -0.0 -3.14"/>
    <axis xyz="1.0 0.0 0.0"/>
  </joint>
  <joint name="swivel_chair_base" type="fixed">
    <parent link="robotiq_arg2f_base_link"/>
    <child link="swivel_chair_base"/>
    <origin xyz="0.0 -0.35 0.35" rpy="-3.14 -0.0 -3.14"/>
    <axis xyz="1.0 0.0 0.0"/>
  </joint>
  <joint name="swivel_chair_base" type="fixed">
    <parent link="robotiq_arg2f_base_link"/>
    <child link="swivel_chair_base"/>
    <origin xyz="0.0 -0.35 0.35" rpy="-3.14 -0.0 -3.14"/>
    <axis xyz="1.0 0.0 0.0"/>
  </joint>
  <joint name="swivel_chair_base" type="fixed">
    <parent link="robotiq_arg2f_base_link"/>
    <child link="swivel_chair_base"/>
    <origin xyz="0.0 -0.35 0.35" rpy="-3.14 -0.0 -3.14"/>
    <axis xyz="1.0 0.0 0.0"/>
  </joint>
  <joint name="swivel_chair_base" type="fixed">
    <parent link="robotiq_arg2f_base_link"/>
    <child link="swivel_chair_base"/>
    <origin xyz="0.0 -0.35 0.35" rpy="-3.14 -0.0 -3.14"/>
    <axis xyz="1.0 0.0 0.0"/>
  </joint>
  <joint name="swivel_chair_base" type="fixed">
    <parent link="robotiq_arg2f_base_link"/>
    <child link="swivel_chair_base"/>
    <origin xyz="0.0 -0.35 0.35" rpy="-3.14 -0.0 -3.14"/>
    <axis xyz="1.0 0.0 0.0"/>
  </joint>
  <joint name="swivel_chair_base" type="fixed">
    <parent link="robotiq_arg2f_base_link"/>
    <child link="swivel_chair_base"/>
    <origin xyz="0.0 -0.35 0.35" rpy="-3.14 -0.0 -3.14"/>
    <axis xyz="1.0 0.0 0.0"/>
  </joint>
  <joint name="swivel_chair_base" type="fixed">
    <parent link="robotiq_arg2f_base_link"/>
    <child link="swivel_chair_base"/>
    <origin xyz="0.0 -0.35 0.35" rpy="-3.14 -0.0 -3.14"/>
    <axis xyz="1.0 0.0 0.0"/>
  </joint>
  <joint name="swivel_chair_base" type="fixed">
    <parent link="robotiq_arg2f_base_link"/>
    <child link="swivel_chair_base"/>
    <origin xyz="0.0 -0.35 0.35" rpy="-3.14 -0.0 -3.14"/>
    <axis xyz="1.0 0.0 0.0"/>
  </joint>
  <joint name="swivel_chair_base" type="fixed">
    <parent link="robotiq_arg2f_base_link"/>
    <child link="swivel_chair_base"/>
    <origin xyz="0.0 -0.35 0.35" rpy="-3.14 -0.0 -3.14"/>
    <axis xyz="1.0 0.0 0.0"/>
  </joint>
  <joint name="swivel_chair_base" type="fixed">
    <parent link="robotiq_arg2f_base_link"/>
    <child link="swivel_chair_base"/>
    <origin xyz="0.0 -0.35 0.35" rpy="-3.14 -0.0 -3.14"/>
    <axis xyz="1.0 0.0 0.0"/>
  </joint>
  <joint name="swivel_chair_base" type="fixed">
    <parent link="robotiq_arg2f_base_link"/>
    <child link="swivel_chair_base"/>
    <origin xyz="0.0 -0.35 0.35" rpy="-3.14 -0.0 -3.14"/>
    <axis xyz="1.0 0.0 0.0"/>
  </joint>
  <joint name="swivel_chair_base" type="fixed">
    <parent link="robotiq_arg2f_base_link"/>
    <child link="swivel_chair_base"/>
    <origin xyz="0.0 -0.35 0.35" rpy="-3.14 -0.0 -3.14"/>
    <axis xyz="1.0 0.0 0.0"/>
  </joint>
  <joint name="swivel_chair_base" type="fixed">
    <parent link="robotiq_arg2f_base_link"/>
    <child link="swivel_chair_base"/>
    <origin xyz="0.0 -0.35 0.35" rpy="-3.14 -0.0 -3.14"/>
    <axis xyz="1.0 0.0 0.0"/>
  </joint>
  <joint name="swivel_chair_base" type="fixed">
    <parent link="robotiq_arg2f_base_link"/>
    <child link="swivel_chair_base"/>
    <origin xyz="0.0 -0.35 0.35" rpy="-3.14 -0.0 -3.14"/>
    <axis xyz="1.0 0.0 0.0"/>
  </joint>
  <joint name="swivel_chair_base_joint" type="fixed">
    <parent link="swivel_chair_base"/>
    <child link="swivel_chair_virtual_theta_link"/>
    <origin xyz="0.0 0.0 0.0" rpy="0.0 -0.0 0.0"/>
    <axis xyz="1.0 0.0 0.0"/>
  </joint>
  <joint name="swivel_chair_y_theta_joint" type="revolute">
    <parent link="swivel_chair_virtual_theta_link"/>
    <child link="swivel_chair_virtual_y_link"/>
    <origin xyz="-0.0 -0.3839999999999999 -1.0289240288650997e-08" rpy="-0.7853981633974482 1.5707962889011904 0.7853981633974482"/>
    <axis xyz="0.0 0.0 1.0"/>
    <limit effort="0.0" velocity="0.5" lower="-3.14" upper="3.14"/>
  </joint>
  <joint name="swivel_chair_x_y_joint" type="prismatic">
    <parent link="swivel_chair_virtual_y_link"/>
    <child link="swivel_chair_virtual_x_link"/>
    <origin xyz="0.0 0.0 0.0" rpy="0.0 -0.0 0.0"/>
    <axis xyz="0.0 1.0 0.0"/>
    <limit effort="0.0" velocity="0.5" lower="-4.0" upper="4.0"/>
  </joint>
  <joint name="swivel_chair_base_x_joint" type="prismatic">
    <parent link="swivel_chair_virtual_x_link"/>
    <child link="swivel_chair_base_link"/>
    <origin xyz="0.0 0.0 0.0" rpy="0.0 -0.0 0.0"/>
    <axis xyz="1.0 0.0 0.0"/>
    <limit effort="0.0" velocity="0.5" lower="-4.0" upper="4.0"/>
  </joint>
</robot>
